Workbook

Sheet Product
A1: ProductID | B1: Product | C1: Price
A2: 101 | B2: Product A | C2: 120
A3: 102 | B3: Product B | C3: 150
A4: 103 | B4: Product C | C4: 200
A5: 104 | B5: Product D | C5: 90
A6: 105 | B6: Product E | C6: 220
A7: 106 | B7: Product F | C7: 130

Sheet Order
A1: OrderID | B1: ProductID | C1: Quantity | D1: TotalPrice
A2: 1 | B2: 101 | C2: 2 | H2: 1.Use VLOOKUP to find the product names for each ProductID in the Orders worksheet.
A3: 2 | B3: 103 | C3: 1
A4: 3 | B4: 105 | C4: 4 | H4: OrderID | I4: ProductID | J4: Quantity | K4: Product Name
A5: 4 | B5: 106 | C5: 3 | H5: 1 | I5: 101 | J5: 2 | K5: =VLOOKUP(I5,Product!$A$1:$B$7,2,FALSE) -> Product A
A6: 5 | B6: 102 | C6: 5 | H6: 2 | I6: 103 | J6: 1 | K6: =VLOOKUP(I6,Product!$A$1:$B$7,2,FALSE) -> Product C
A7: 6 | B7: 104 | C7: 6 | H7: 3 | I7: 105 | J7: 4 | K7: =VLOOKUP(I7,Product!$A$1:$B$7,2,FALSE) -> Product E
H8: 4 | I8: 106 | J8: 3 | K8: =VLOOKUP(I8,Product!$A$1:$B$7,2,FALSE) -> Product F
H9: 5 | I9: 102 | J9: 5 | K9: =VLOOKUP(I9,Product!$A$1:$B$7,2,FALSE) -> Product B
H10: 6 | I10: 104 | J10: 6 | K10: =VLOOKUP(I10,Product!$A$1:$B$7,2,FALSE) -> Product D
H12: 2.Use VLOOKUP to find the price for each ProductID in the Orders worksheet, then calculate the TotalPrice by multiplying the Quantity by the Product Price.
H14: OrderID | I14: ProductID | J14: Quantity | K14: Price
H15: 1 | I15: 101 | J15: 2 | K15: =VLOOKUP(I15,Product!$A$1:$C$7,3,FALSE) -> 120
H16: 2 | I16: 103 | J16: 1 | K16: =VLOOKUP(I16,Product!$A$1:$C$7,3,FALSE) -> 200
H17: 3 | I17: 105 | J17: 4 | K17: =VLOOKUP(I17,Product!$A$1:$C$7,3,FALSE) -> 220
H18: 4 | I18: 106 | J18: 3 | K18: =VLOOKUP(I18,Product!$A$1:$C$7,3,FALSE) -> 130
H19: 5 | I19: 102 | J19: 5 | K19: =VLOOKUP(I19,Product!$A$1:$C$7,3,FALSE) -> 150
H20: 6 | I20: 104 | J20: 6 | K20: =VLOOKUP(I20,Product!$A$1:$C$7,3,FALSE) -> 90
H22: 3.Use VLOOKUP to check if there are any ProductIDs in the Orders worksheet that do not exist in the Products worksheet.
A24: OrderID | B24: ProductID | C24: Quantity | H24: OrderID | I24: ProductID | J24: Quantity | K24: Result
A25: 1 | B25: 101 | C25: 2 | H25: 1 | I25: 101 | J25: 2 | K25: =IF(ISNA(VLOOKUP(I25,Product!$A$1:$C$7,1,0)),"Not Exist","Exist") -> Exist
A26: 2 | B26: 103 | C26: 1 | H26: 2 | I26: 103 | J26: 1 | K26: =IF(ISNA(VLOOKUP(I26,Product!$A$1:$C$7,1,0)),"Not Exist","Exist") -> Exist
A27: 3 | B27: 105 | C27: 4 | H27: 3 | I27: 105 | J27: 4 | K27: =IF(ISNA(VLOOKUP(I27,Product!$A$1:$C$7,1,0)),"Not Exist","Exist") -> Exist
A28: 4 | B28: 106 | C28: 3 | H28: 4 | I28: 106 | J28: 3 | K28: =IF(ISNA(VLOOKUP(I28,Product!$A$1:$C$7,1,0)),"Not Exist","Exist") -> Exist
A29: 5 | B29: 102 | C29: 5 | H29: 5 | I29: 102 | J29: 5 | K29: =IF(ISNA(VLOOKUP(I29,Product!$A$1:$C$7,1,0)),"Not Exist","Exist") -> Exist
A30: 6 | B30: 104 | C30: 6 | H30: 6 | I30: 104 | J30: 6 | K30: =IF(ISNA(VLOOKUP(I30,Product!$A$1:$C$7,1,0)),"Not Exist","Exist") -> Exist
A31: 7 | B31: 107 | C31: 8 | H31: 7 | I31: 107 | J31: 8 | K31: =IF(ISNA(VLOOKUP(I31,Product!$A$1:$C$7,1,0)),"Not Exist","Exist") -> Not Exist
H33: 4.Assume a discount of 10% is given on all products. Use VLOOKUP to find the original price and then calculate the discounted price.
H35: ProductID | I35: Quantity | J35: Price | K35: Discount Price | L35: Discount Amount
H36: 101 | I36: 2 | J36: =VLOOKUP(H36,Product!$A$1:$C$7,3,FALSE) -> 120 | K36: =J36-(J36*10%) -> 108 | L36: =J36-K36 -> 12
H37: 103 | I37: 1 | J37: =VLOOKUP(H37,Product!$A$1:$C$7,3,FALSE) -> 200 | K37: =J37-(J37*10%) -> 180 | L37: =J37-K37 -> 20
H38: 105 | I38: 4 | J38: =VLOOKUP(H38,Product!$A$1:$C$7,3,FALSE) -> 220 | K38: =J38-(J38*10%) -> 198 | L38: =J38-K38 -> 22
H39: 106 | I39: 3 | J39: =VLOOKUP(H39,Product!$A$1:$C$7,3,FALSE) -> 130 | K39: =J39-(J39*10%) -> 117 | L39: =J39-K39 -> 13
H40: 102 | I40: 5 | J40: =VLOOKUP(H40,Product!$A$1:$C$7,3,FALSE) -> 150 | K40: =J40-(J40*10%) -> 135 | L40: =J40-K40 -> 15
H41: 104 | I41: 6 | J41: =VLOOKUP(H41,Product!$A$1:$C$7,3,FALSE) -> 90 | K41: =J41-(J41*10%) -> 81 | L41: =J41-K41 -> 9
H43: 5.Use VLOOKUP to find the price for each ProductID and then calculate the order value. Find the maximum order value from the list.
H45: OrderID | I45: ProductID | J45: Quantity | K45: Price | L45: Order Value | M45: Maximum Order Value
H46: 1 | I46: 101 | J46: 2 | K46: 120 | L46: =J46*K46 -> 240 | M46: =MAX(L46:L51) -> 1100
H47: 2 | I47: 103 | J47: 1 | K47: 150 | L47: =J47*K47 -> 150
H48: 3 | I48: 105 | J48: 4 | K48: 200 | L48: =J48*K48 -> 800
...
